<?xml version="1.0" encoding="utf-8" ?>
<!-- This URDF was automatically created by SolidWorks to URDF Exporter! Originally created by Stephen Brawner (brawner@gmail.com) 
     Commit Version: 1.6.0-4-g7f85cfe  Build Version: 1.6.7995.38578
     For more information, please see http://wiki.ros.org/sw_urdf_exporter -->
<robot name="ur">
    <link name="world" />
    <joint name="fixed_base_joint" type="fixed">
        <parent link="world" />
        <child link="base_link" />
        <origin xyz="0 0 1.5" rpy="0 0 0" />
    </joint>
    <link name="base_link">
        <inertial>
            <origin xyz="-0.0896989193830348 0.0150148258843391 0.0433636232679913" rpy="0 0 0" />
            <mass value="1.20836431261136" />
            <inertia ixx="0.0031298465636462" ixy="-2.71013741013438E-06" ixz="-8.65173386737269E-07" iyy="0.00496370853366527" iyz="-5.11891855838858E-05" izz="0.00356040653491963" />
        </inertial>
        <visual>
            <origin xyz="0 0 0" rpy="0 0 0" />
            <geometry>
                <mesh filename="package://ur/meshes/base_link.STL" />
            </geometry>
            <material name="">
                <color rgba="0.792156862745098 0.819607843137255 0.933333333333333 1" />
            </material>
        </visual>
        <collision>
            <origin xyz="0 0 0" rpy="0 0 0" />
            <geometry>
                <mesh filename="package://ur/meshes/base_link.STL" />
            </geometry>
        </collision>
    </link>
    <link name="link1">
        <inertial>
            <origin xyz="1.0263E-07 0.083389 0.012893" rpy="0 0 0" />
            <mass value="3.5021" />
            <inertia ixx="0.014442" ixy="-1.6274E-07" ixz="1.037E-07" iyy="0.012018" iyz="-0.00017856" izz="0.012835" />
        </inertial>
        <visual>
            <origin xyz="0 0 0" rpy="0 0 0" />
            <geometry>
                <mesh filename="package://ur/meshes/link1.STL" />
            </geometry>
            <material name="">
                <color rgba="0.79216 0.81961 0.93333 1" />
            </material>
        </visual>
        <collision>
            <origin xyz="0 0 0" rpy="0 0 0" />
            <geometry>
                <mesh filename="package://ur/meshes/link1.STL" />
            </geometry>
        </collision>
    </link>
    <joint name="joint1" type="revolute">
        <origin xyz="-0.089616 -0.04445 0.053838" rpy="1.5708 0 1.9734" />
        <parent link="base_link" />
        <child link="link1" />
        <axis xyz="0 -1 0" />
        <limit lower="-3.14" upper="3.14" effort="100" velocity="2" />
    </joint>
    <link name="link2">
        <inertial>
            <origin xyz="-9.186E-06 0.21122 0.055506" rpy="0 0 0" />
            <mass value="5.8521" />
            <inertia ixx="0.42174" ixy="2.8426E-06" ixz="-3.4637E-08" iyy="0.018386" iyz="0.00092667" izz="0.41882" />
        </inertial>
        <visual>
            <origin xyz="0 0 0" rpy="0 0 0" />
            <geometry>
                <mesh filename="package://ur/meshes/link2.STL" />
            </geometry>
            <material name="">
                <color rgba="0.79216 0.81961 0.93333 1" />
            </material>
        </visual>
        <collision>
            <origin xyz="0 0 0" rpy="0 0 0" />
            <geometry>
                <mesh filename="package://ur/meshes/link2.STL" />
            </geometry>
        </collision>
    </link>
    <joint name="joint2" type="revolute">
        <origin xyz="0 0.0814 0.12148" rpy="0 0 1.9839" />
        <parent link="link1" />
        <child link="link2" />
        <axis xyz="0 0 -1" />
        <limit lower="-3.14" upper="3.14" effort="100" velocity="2" />
    </joint>
    <link name="link3">
        <inertial>
            <origin xyz="5.0262E-06 0.26577 -0.077247" rpy="0 0 0" />
            <mass value="4.6232" />
            <inertia ixx="0.19846" ixy="2.607E-06" ixz="-6.2585E-07" iyy="0.0062667" iyz="0.0058805" izz="0.19757" />
        </inertial>
        <visual>
            <origin xyz="0 0 0" rpy="0 0 0" />
            <geometry>
                <mesh filename="package://ur/meshes/link3.STL" />
            </geometry>
            <material name="">
                <color rgba="0.79216 0.81961 0.93333 1" />
            </material>
        </visual>
        <collision>
            <origin xyz="0 0 0" rpy="0 0 0" />
            <geometry>
                <mesh filename="package://ur/meshes/link3.STL" />
            </geometry>
        </collision>
    </link>
    <joint name="joint3" type="revolute">
        <origin xyz="0 0.6126 0" rpy="0 0 -0.32185" />
        <parent link="link2" />
        <child link="link3" />
        <axis xyz="0 0 1" />
        <limit lower="-3.14" upper="3.14" effort="100" velocity="2" />
    </joint>
    <link name="link4">
        <inertial>
            <origin xyz="-2.2928E-06 0.0015828 0.036716" rpy="0 0 0" />
            <mass value="0.95283" />
            <inertia ixx="0.0018186" ixy="3.6596E-08" ixz="-2.4379E-08" iyy="0.0015057" iyz="-4.6033E-05" izz="0.0013238" />
        </inertial>
        <visual>
            <origin xyz="0 0 0" rpy="0 0 0" />
            <geometry>
                <mesh filename="package://ur/meshes/link4.STL" />
            </geometry>
            <material name="">
                <color rgba="0.79216 0.81961 0.93333 1" />
            </material>
        </visual>
        <collision>
            <origin xyz="0 0 0" rpy="0 0 0" />
            <geometry>
                <mesh filename="package://ur/meshes/link4.STL" />
            </geometry>
        </collision>
    </link>
    <joint name="joint4" type="revolute">
        <origin xyz="0 0.57155 0" rpy="0 0 -0.65114" />
        <parent link="link3" />
        <child link="link4" />
        <axis xyz="0 0 -1" />
        <limit lower="-3.14" upper="3.14" effort="100" velocity="2" />
    </joint>
    <link name="link5">
        <inertial>
            <origin xyz="-4.3237E-08 0.11023 0.0017252" rpy="0 0 0" />
            <mass value="0.8529" />
            <inertia ixx="0.0014347" ixy="-1.5863E-10" ixz="7.2416E-09" iyy="0.0012218" iyz="-3.6762E-05" izz="0.0011216" />
        </inertial>
        <visual>
            <origin xyz="0 0 0" rpy="0 0 0" />
            <geometry>
                <mesh filename="package://ur/meshes/link5.STL" />
            </geometry>
            <material name="">
                <color rgba="0.79216 0.81961 0.93333 1" />
            </material>
        </visual>
        <collision>
            <origin xyz="0 0 0" rpy="0 0 0" />
            <geometry>
                <mesh filename="package://ur/meshes/link5.STL" />
            </geometry>
        </collision>
    </link>
    <joint name="joint5" type="revolute">
        <origin xyz="0 0 0.052666" rpy="3.1416 1.009 3.1416" />
        <parent link="link4" />
        <child link="link5" />
        <axis xyz="0 -1 0" />
        <limit lower="-3.14" upper="3.14" effort="100" velocity="2" />
    </joint>
    <link name="link6">
        <inertial>
            <origin xyz="3.6479E-10 -0.00011146 0.01388" rpy="0 0 0" />
            <mass value="0.35025" />
            <inertia ixx="0.00026377" ixy="-1.1782E-11" ixz="3.1115E-12" iyy="0.00026524" iyz="8.5439E-09" izz="0.00034693" />
        </inertial>
        <visual>
            <origin xyz="0 0 0" rpy="0 0 0" />
            <geometry>
                <mesh filename="package://ur/meshes/link6.STL" />
            </geometry>
            <material name="">
                <color rgba="0.79216 0.81961 0.93333 1" />
            </material>
        </visual>
        <collision>
            <origin xyz="0 0 0" rpy="0 0 0" />
            <geometry>
                <mesh filename="package://ur/meshes/link6.STL" />
            </geometry>
        </collision>
    </link>
    <joint name="joint6" type="revolute">
        <origin xyz="0 0.11985 0.070785" rpy="0 0 -2.5958" />
        <parent link="link5" />
        <child link="link6" />
        <axis xyz="0 0 -1" />
        <limit lower="-3.14" upper="3.14" effort="100" velocity="2" />
    </joint>
    <transmission name="trans_joint1">
        <type>transmission_interface/SimpleTransmission</type>
        <joint name="joint1">
            <hardwareInterface>hardware_interface/PositionJointInterface</hardwareInterface>
        </joint>
        <actuator name="joint1_motor">
            <hardwareInterface>hardware_interface/PositionJointInterface</hardwareInterface>
            <mechanicalReduction>1</mechanicalReduction>
        </actuator>
    </transmission>
    <transmission name="trans_joint2">
        <type>transmission_interface/SimpleTransmission</type>
        <joint name="joint2">
            <hardwareInterface>hardware_interface/PositionJointInterface</hardwareInterface>
        </joint>
        <actuator name="joint2_motor">
            <hardwareInterface>hardware_interface/PositionJointInterface</hardwareInterface>
            <mechanicalReduction>1</mechanicalReduction>
        </actuator>
    </transmission>
    <transmission name="trans_joint3">
        <type>transmission_interface/SimpleTransmission</type>
        <joint name="joint3">
            <hardwareInterface>hardware_interface/PositionJointInterface</hardwareInterface>
        </joint>
        <actuator name="joint3_motor">
            <hardwareInterface>hardware_interface/PositionJointInterface</hardwareInterface>
            <mechanicalReduction>1</mechanicalReduction>
        </actuator>
    </transmission>
    <transmission name="trans_joint4">
        <type>transmission_interface/SimpleTransmission</type>
        <joint name="joint4">
            <hardwareInterface>hardware_interface/PositionJointInterface</hardwareInterface>
        </joint>
        <actuator name="joint4_motor">
            <hardwareInterface>hardware_interface/PositionJointInterface</hardwareInterface>
            <mechanicalReduction>1</mechanicalReduction>
        </actuator>
    </transmission>
    <transmission name="trans_joint5">
        <type>transmission_interface/SimpleTransmission</type>
        <joint name="joint5">
            <hardwareInterface>hardware_interface/PositionJointInterface</hardwareInterface>
        </joint>
        <actuator name="joint5_motor">
            <hardwareInterface>hardware_interface/PositionJointInterface</hardwareInterface>
            <mechanicalReduction>1</mechanicalReduction>
        </actuator>
    </transmission>
    <transmission name="trans_joint6">
        <type>transmission_interface/SimpleTransmission</type>
        <joint name="joint6">
            <hardwareInterface>hardware_interface/PositionJointInterface</hardwareInterface>
        </joint>
        <actuator name="joint6_motor">
            <hardwareInterface>hardware_interface/PositionJointInterface</hardwareInterface>
            <mechanicalReduction>1</mechanicalReduction>
        </actuator>
    </transmission>
    <gazebo>
        <plugin name="gazebo_ros_control" filename="libgazebo_ros_control.so">
            <robotNamespace>/</robotNamespace>
        </plugin>
    </gazebo>
</robot>

